Workbook

Sheet Dashboard
B2: Mesa de Ayuda: tablero de indicadores
B3: Los datos vienen de la hoja Datos. Al reemplazarlos, todo el tablero se recalcula solo.
C5: Total tickets | D5: Cerrados | E5: Pendientes | F5: % SLA cumplido | G5: Horas promedio de solución | H5: % escalados a nivel 2
C6: =COUNTA(Datos!$A$2:$A$5000) -> 300 | D6: =COUNTIF(Datos!$F$2:$F$5000,"cerrado") -> 272 | E6: =C6-D6 -> 28 | F6: =IFERROR(COUNTIFS(Datos!$F$2:$F$5000,"cerrado",Datos!$L$2:$L$5000,"si")/D6,0) -> 0.68382353 | G6: =IFERROR(AVERAGEIFS(Datos!$J$2:$J$5000,Datos!$F$2:$F$5000,"cerrado"),0) -> 24.424632 | H6: =IFERROR(COUNTIF(Datos!$G$2:$G$5000,2)/C6,0) -> 0.17
B9: Tickets por estado | E9: Tickets por categoría
B10: Estado | C10: Tickets | E10: Categoría | F10: Tickets
B11: abierto | C11: =COUNTIF(Datos!$F$2:$F$5000,B11) -> 8 | E11: acceso | F11: =COUNTIF(Datos!$D$2:$D$5000,E11) -> 46
B12: en_proceso | C12: =COUNTIF(Datos!$F$2:$F$5000,B12) -> 14 | E12: error | F12: =COUNTIF(Datos!$D$2:$D$5000,E12) -> 60
B13: escalado | C13: =COUNTIF(Datos!$F$2:$F$5000,B13) -> 6 | E13: datos | F13: =COUNTIF(Datos!$D$2:$D$5000,E13) -> 56
B14: cerrado | C14: =COUNTIF(Datos!$F$2:$F$5000,B14) -> 272 | E14: rendimiento | F14: =COUNTIF(Datos!$D$2:$D$5000,E14) -> 65
E15: consulta | F15: =COUNTIF(Datos!$D$2:$D$5000,E15) -> 73
B18: Cumplimiento de SLA por prioridad (solo cerrados)
B19: Prioridad | C19: SLA (horas) | D19: Cerrados | E19: Horas promedio | F19: % SLA cumplido
B20: alta | C20: 4 | D20: =COUNTIFS(Datos!$E$2:$E$5000,B20,Datos!$F$2:$F$5000,"cerrado") -> 56 | E20: =IFERROR(AVERAGEIFS(Datos!$J$2:$J$5000,Datos!$E$2:$E$5000,B20,Datos!$F$2:$F$5000,"cerrado"),0) -> 3.2357143 | F20: =IFERROR(COUNTIFS(Datos!$E$2:$E$5000,B20,Datos!$F$2:$F$5000,"cerrado",Datos!$L$2:$L$5000,"si")/D20,0) -> 0.66071429
B21: media | C21: 24 | D21: =COUNTIFS(Datos!$E$2:$E$5000,B21,Datos!$F$2:$F$5000,"cerrado") -> 136 | E21: =IFERROR(AVERAGEIFS(Datos!$J$2:$J$5000,Datos!$E$2:$E$5000,B21,Datos!$F$2:$F$5000,"cerrado"),0) -> 19.009559 | F21: =IFERROR(COUNTIFS(Datos!$E$2:$E$5000,B21,Datos!$F$2:$F$5000,"cerrado",Datos!$L$2:$L$5000,"si")/D21,0) -> 0.67647059
B22: baja | C22: 72 | D22: =COUNTIFS(Datos!$E$2:$E$5000,B22,Datos!$F$2:$F$5000,"cerrado") -> 80 | E22: =IFERROR(AVERAGEIFS(Datos!$J$2:$J$5000,Datos!$E$2:$E$5000,B22,Datos!$F$2:$F$5000,"cerrado"),0) -> 48.4625 | F22: =IFERROR(COUNTIFS(Datos!$E$2:$E$5000,B22,Datos!$F$2:$F$5000,"cerrado",Datos!$L$2:$L$5000,"si")/D22,0) -> 0.7125
B23: SLA (horas) en azul: supuesto del proyecto (alta 4, media 24, baja 72).
B25: Problemas más repetidos (para la base de conocimiento)
B26: Problema | C26: Veces | D26: Categoría
B27: No puedo iniciar sesión | C27: =COUNTIF(Datos!$B$2:$B$5000,B27) -> 17 | D27: acceso
B28: Usuario bloqueado | C28: =COUNTIF(Datos!$B$2:$B$5000,B28) -> 13 | D28: acceso
B29: Olvidé mi contraseña | C29: =COUNTIF(Datos!$B$2:$B$5000,B29) -> 10 | D29: acceso
B30: Solicitud de usuario nuevo | C30: =COUNTIF(Datos!$B$2:$B$5000,B30) -> 6 | D30: acceso
B31: Error 500 al guardar | C31: =COUNTIF(Datos!$B$2:$B$5000,B31) -> 16 | D31: error
B32: El botón de enviar no responde | C32: =COUNTIF(Datos!$B$2:$B$5000,B32) -> 16 | D32: error
B33: Error al cargar archivo | C33: =COUNTIF(Datos!$B$2:$B$5000,B33) -> 28 | D33: error
B34: El reporte no cuadra | C34: =COUNTIF(Datos!$B$2:$B$5000,B34) -> 16 | D34: datos
B35: Registro duplicado | C35: =COUNTIF(Datos!$B$2:$B$5000,B35) -> 19 | D35: datos
B36: No aparece un registro ingresado | C36: =COUNTIF(Datos!$B$2:$B$5000,B36) -> 21 | D36: datos
B37: El sistema está lento | C37: =COUNTIF(Datos!$B$2:$B$5000,B37) -> 19 | D37: rendimiento
B38: La página tarda en cargar | C38: =COUNTIF(Datos!$B$2:$B$5000,B38) -> 18 | D38: rendimiento
... B42: Dónde veo mis casos | C42: =COUNTIF(Datos!$B$2:$B$5000,B42) -> 30 | D42: consulta

Sheet Datos
A1: id | B1: titulo | C1: tipo | D1: categoria | E1: prioridad | F1: estado | G1: nivel | H1: creado_en | I1: cerrado_en | J1: horas_resolucion | K1: sla_horas | L1: sla_cumplido
A2: 1 | B2: El reporte no cuadra | C2: incidente | D2: datos | E2: baja | F2: cerrado | G2: 2 | H2: 46289.562 | I2: 46292.085 | J2: 60.6 | K2: 72 | L2: si
A3: 2 | B3: Dónde veo mis casos | C3: requerimiento | D3: consulta | E3: media | F3: cerrado | G3: 2 | H3: 46214.382 | I3: 46216.165 | J3: 42.8 | K3: 24 | L3: no
A4: 3 | B4: No puedo iniciar sesión | C4: incidente | D4: acceso | E4: baja | F4: cerrado | G4: 2 | H4: 46258.444 | I4: 46258.802 | J4: 8.6 | K4: 72 | L4: si
A5: 4 | B5: No puedo iniciar sesión | C5: incidente | D5: acceso | E5: media | F5: cerrado | G5: 1 | H5: 46238.497 | I5: 46239.706 | J5: 29 | K5: 24 | L5: no
A6: 5 | B6: Error al cargar archivo | C6: incidente | D6: error | E6: media | F6: cerrado | G6: 1 | H6: 46217.312 | I6: 46217.735 | J6: 10.2 | K6: 24 | L6: si
A7: 6 | B7: No aparece un registro ingresado | C7: incidente | D7: datos | E7: media | F7: cerrado | G7: 1 | H7: 46209.469 | I7: 46210.474 | J7: 24.1 | K7: 24 | L7: no
A8: 7 | B8: Se cae al generar reportes | C8: incidente | D8: rendimiento | E8: alta | F8: cerrado | G8: 1 | H8: 46226.856 | I8: 46227.058 | J8: 4.9 | K8: 4 | L8: no
A9: 8 | B9: Error al cargar archivo | C9: incidente | D9: error | E9: baja | F9: cerrado | G9: 1 | H9: 46258.488 | I9: 46259.265 | J9: 18.7 | K9: 72 | L9: si
A10: 9 | B10: El reporte no cuadra | C10: incidente | D10: datos | E10: media | F10: cerrado | G10: 1 | H10: 46239.949 | I10: 46239.978 | J10: 0.7 | K10: 24 | L10: si
A11: 10 | B11: El reporte no cuadra | C11: incidente | D11: datos | E11: media | F11: cerrado | G11: 1 | H11: 46247.933 | I11: 46248.157 | J11: 5.4 | K11: 24 | L11: si
A12: 11 | B12: No aparece un registro ingresado | C12: incidente | D12: datos | E12: baja | F12: cerrado | G12: 1 | H12: 46218.745 | I12: 46218.826 | J12: 2 | K12: 72 | L12: si
A13: 12 | B13: El sistema está lento | C13: incidente | D13: rendimiento | E13: media | F13: cerrado | G13: 1 | H13: 46243.418 | I13: 46244.085 | J13: 16 | K13: 24 | L13: si
... A29: 28 | B29: El botón de enviar no responde | C29: incidente | D29: error | E29: media | F29: cerrado | G29: 1 | H29: 46263.675 | I29: 46264.835 | J29: 27.9 | K29: 24 | L29: no
A30: 29 | B30: Se cae al generar reportes | C30: incidente | D30: rendimiento | E30: baja | F30: abierto | G30: 1 | H30: 46286.609 | K30: 72 | L30: no
A31: 30 | B31: La página tarda en cargar | C31: incidente | D31: rendimiento | E31: baja | F31: cerrado | G31: 1 | H31: 46204.868 | I31: 46206.207 | J31: 32.1 | K31: 72 | L31: si
A32: 31 | B32: Error al cargar archivo | C32: incidente | D32: error | E32: alta | F32: cerrado | G32: 1 | H32: 46228.649 | I32: 46228.845 | J32: 4.7 | K32: 4 | L32: no
A33: 32 | B33: Olvidé mi contraseña | C33: incidente | D33: acceso | E33: media | F33: cerrado | G33: 1 | H33: 46241.523 | I33: 46242.527 | J33: 24.1 | K33: 24 | L33: no
A34: 33 | B34: El botón de enviar no responde | C34: incidente | D34: error | E34: alta | F34: cerrado | G34: 1 | H34: 46216.765 | I34: 46216.86 | J34: 2.3 | K34: 4 | L34: si
A35: 34 | B35: Olvidé mi contraseña | C35: incidente | D35: acceso | E35: media | F35: cerrado | G35: 1 | H35: 46240.387 | I35: 46241.731 | J35: 32.3 | K35: 24 | L35: no
A36: 35 | B36: Dónde veo mis casos | C36: requerimiento | D36: consulta | E36: media | F36: escalado | G36: 2 | H36: 46275.581 | K36: 24 | L36: no
A37: 36 | B37: El botón de enviar no responde | C37: incidente | D37: error | E37: baja | F37: cerrado | G37: 1 | H37: 46288.376 | I37: 46291.981 | J37: 86.5 | K37: 72 | L37: no
A38: 37 | B38: El sistema está lento | C38: incidente | D38: rendimiento | E38: baja | F38: cerrado | G38: 1 | H38: 46228.073 | I38: 46231.256 | J38: 76.4 | K38: 72 | L38: no
A39: 38 | B39: La página tarda en cargar | C39: incidente | D39: rendimiento | E39: media | F39: cerrado | G39: 1 | H39: 46289.033 | I39: 46289.732 | J39: 16.8 | K39: 24 | L39: si
A40: 39 | B40: Cómo cambiar mi correo | C40: requerimiento | D40: consulta | E40: baja | F40: cerrado | G40: 1 | H40: 46230.94 | I40: 46231.242 | J40: 7.3 | K40: 72 | L40: si
A41: 40 | B41: No puedo iniciar sesión | C41: incidente | D41: acceso | E41: alta | F41: cerrado | G41: 2 | H41: 46220.777 | I41: 46220.806 | J41: 0.7 | K41: 4 | L41: si
A42: 41 | B42: No puedo iniciar sesión | C42: incidente | D42: acceso | E42: baja | F42: en_proceso | G42: 1 | H42: 46269.111 | K42: 72 | L42: no
A43: 42 | B43: Error 500 al guardar | C43: incidente | D43: error | E43: baja | F43: cerrado | G43: 1 | H43: 46263.656 | I43: 46266.906 | J43: 78 | K43: 72 | L43: no
A44: 43 | B44: El reporte no cuadra | C44: incidente | D44: datos | E44: media | F44: cerrado | G44: 2 | H44: 46229.928 | I44: 46231.822 | J44: 45.4 | K44: 24 | L44: no
A45: 44 | B45: Solicitud de usuario nuevo | C45: requerimiento | D45: acceso | E45: baja | F45: cerrado | G45: 1 | H45: 46276.276 | I45: 46280.333 | J45: 97.4 | K45: 72 | L45: no
A46: 45 | B46: Usuario bloqueado | C46: incidente | D46: acceso | E46: media | F46: cerrado | G46: 1 | H46: 46227.442 | I46: 46227.812 | J46: 8.9 | K46: 24 | L46: si
A47: 46 | B47: No puedo iniciar sesión | C47: incidente | D47: acceso | E47: baja | F47: cerrado | G47: 1 | H47: 46271.729 | I47: 46275.219 | J47: 83.8 | K47: 72 | L47: no
A48: 47 | B48: Olvidé mi contraseña | C48: incidente | D48: acceso | E48: baja | F48: cerrado | G48: 1 | H48: 46230.503 | I48: 46231.847 | J48: 32.3 | K48: 72 | L48: si
A49: 48 | B49: El sistema está lento | C49: incidente | D49: rendimiento | E49: media | F49: cerrado | G49: 1 | H49: 46287.779 | I49: 46288.015 | J49: 5.7 | K49: 24 | L49: si
A50: 49 | B50: Registro duplicado | C50: incidente | D50: datos | E50: alta | F50: cerrado | G50: 2 | H50: 46286.127 | I50: 46286.39 | J50: 6.3 | K50: 4 | L50: no
A51: 50 | B51: Error al cargar archivo | C51: incidente | D51: error | E51: media | F51: cerrado | G51: 1 | H51: 46236.862 | I51: 46236.911 | J51: 1.2 | K51: 24 | L51: si
A52: 51 | B52: Dónde veo mis casos | C52: requerimiento | D52: consulta | E52: media | F52: cerrado | G52: 1 | H52: 46284.172 | I52: 46285.515 | J52: 32.2 | K52: 24 | L52: no
A53: 52 | B53: El botón de enviar no responde | C53: incidente | D53: error | E53: media | F53: cerrado | G53: 1 | H53: 46280.065 | I53: 46280.222 | J53: 3.8 | K53: 24 | L53: si
A54: 53 | B54: Registro duplicado | C54: incidente | D54: datos | E54: alta | F54: cerrado | G54: 2 | H54: 46257.915 | I54: 46257.984 | J54: 1.7 | K54: 4 | L54: si
... A86: 85 | B86: El botón de enviar no responde | C86: incidente | D86: error | E86: media | F86: cerrado | G86: 1 | H86: 46265.69 | I86: 46266.176 | J86: 11.7 | K86: 24 | L86: si
...

Sheet Instrucciones
B2: Cómo usar este archivo
B3: La hoja Datos tiene los tickets exportados de la API (tickets.csv). Para actualizarlos con datos nuevos:
B5: Opción A: pegar los datos (rápido)
B6: 1. Descarga https://mesa-ayuda-4wfr.onrender.com/reportes/tickets.csv
B7: 2. Ábrelo, copia todo desde la fila 2 y pégalo en la hoja Datos desde la celda A2 (mismas columnas, mismo orden).
B8: 3. El Dashboard se recalcula solo.
B10: Opción B: Power Query (lo que piden en las ofertas de datos)
B11: 1. En un libro nuevo: Datos > Obtener datos > Desde archivo > Desde texto/CSV > escoge tickets.csv.
B12: 2. En la ventana, pulsa Transformar datos para abrir el editor de Power Query.
B13: 3. Revisa los tipos de columna: creado_en y cerrado_en = Fecha y hora; horas_resolucion = Número decimal;
B14: si los decimales salen mal, cambia el tipo usando 'Usar configuración regional' > Inglés (Estados Unidos).
B15: 4. Agrega una columna: Agregar columna > Columna personalizada > nombre 'mes', fórmula: Date.ToText([creado_en], "yyyy-MM").
... B28: 4. Guarda como MesaAyuda.pbix y súbelo al repositorio junto con un pantallazo del tablero.
